1INCHUSDT,AAVEUSDT,ADAUSDT,AGIXUSDT,ALGOUSDT,ANKRUSDT,APEUSDT,APTUSDT,ARBUSDT,ARUSDT,ATOMUSDT,AVAXUSDT,AXSUSDT,BCHUSDT,BICOUSDT,BLURUSDT,BNBUSDT,BOBAUSDT,BTCUSDT,C98USDT,CELOUSDT,CHZUSDT,COMPUSDT,CRVUSDT,CTCUSDT,DOGEUSDT,DOTUSDT,DYDXUSDT,EGLDUSDT,ENJUSDT,ENSUSDT,EOSUSDT,ETCUSDT,ETHUSDT,ETHWUSDT,FETUSDT,FILUSDT,FITFIUSDT,FLOWUSDT,FLRUSDT,FTMUSDT,FXSUSDT,GALAUSDT,GALUSDT,GLMRUSDT,GMTUSDT,GMXUSDT,GPTUSDT,GRTUSDT,HBARUSDT,HFTUSDT,HNTUSDT,HOOKUSDT,HOTUSDT,ICPUSDT,ICXUSDT,IMXUSDT,INJUSDT,JASMYUSDT,KAVAUSDT,KDAUSDT,KLAYUSDT,KSMUSDT,LDOUSDT,LINKUSDT,LOOKSUSDT,LRCUSDT,LTCUSDT,MAGICUSDT,MANAUSDT,MASKUSDT,MATICUSDT,MINAUSDT,NEARUSDT,OMGUSDT,ONEUSDT,OPUSDT,PEOPLEUSDT,QTUMUSDT,RDNTUSDT,RNDRUSDT,ROSEUSDT,RUNEUSDT,SANDUSDT,SCUSDT,SLPUSDT,SNXUSDT,SOLUSDT,SPELLUSDT,SSVUSDT,STGUSDT,STXUSDT,SUSHIUSDT,THETAUSDT,TRXUSDT,TWTUSDT,UNIUSDT,WAVESUSDT,WOOUSDT,XLMUSDT,XRPUSDT,XTZUSDT,YFIUSDT,ZENUSDT,ZILUSDT,ZRXUSDT2024-05-31 21:21:48,331 ERROR 
Traceback (most recent call last):
  File "/home/gerka/Desktop/kekMyPek/vol_bot/main.py", line 43, in main
    kLineDf = getKline(symbol, interval, Limit)
              ^^^^^^^^^^^^^^^^^^^^^^^^^^^^^^^^^
  File "/home/gerka/Desktop/kekMyPek/vol_bot/getData.py", line 21, in getKline
    rawReq = session.get_kline(
             ^^^^^^^^^^^^^^^^^^
  File "/home/gerka/Desktop/kekMyPek/vol_bot/venv/lib/python3.11/site-packages/pybit/_v5_market.py", line 33, in get_kline
    return self._submit_request(
           ^^^^^^^^^^^^^^^^^^^^^
  File "/home/gerka/Desktop/kekMyPek/vol_bot/venv/lib/python3.11/site-packages/pybit/_http_manager.py", line 379, in _submit_request
    raise InvalidRequestError(
pybit.exceptions.InvalidRequestError: The requested symbol is invalid. (ErrCode: 10001) (ErrTime: 16:21:48).
Request → GET https://api.bybit.com/v5/market/kline: category=linear&end=False&interval=60&limit=100&start=False&symbol=.
2024-05-31 21:24:59,599 ERROR GPTUSDT
Traceback (most recent call last):
  File "/home/gerka/Desktop/kekMyPek/vol_bot/main.py", line 46, in main
    kLineDf = getKline(symbol, interval, Limit)
              ^^^^^^^^^^^^^^^^^^^^^^^^^^^^^^^^^
  File "/home/gerka/Desktop/kekMyPek/vol_bot/getData.py", line 36, in getKline
    cleanDf['Date'] = dataFrame.iloc[:,0].apply(lambda x: x[0:-3]) #.astype(np.int64)/1000
                      ~~~~~~~~~~~~~~^^^^^
  File "/home/gerka/Desktop/kekMyPek/vol_bot/venv/lib/python3.11/site-packages/pandas/core/indexing.py", line 1184, in __getitem__
    return self._getitem_tuple(key)
           ^^^^^^^^^^^^^^^^^^^^^^^^
  File "/home/gerka/Desktop/kekMyPek/vol_bot/venv/lib/python3.11/site-packages/pandas/core/indexing.py", line 1690, in _getitem_tuple
    tup = self._validate_tuple_indexer(tup)
          ^^^^^^^^^^^^^^^^^^^^^^^^^^^^^^^^^
  File "/home/gerka/Desktop/kekMyPek/vol_bot/venv/lib/python3.11/site-packages/pandas/core/indexing.py", line 966, in _validate_tuple_indexer
    self._validate_key(k, i)
  File "/home/gerka/Desktop/kekMyPek/vol_bot/venv/lib/python3.11/site-packages/pandas/core/indexing.py", line 1592, in _validate_key
    self._validate_integer(key, axis)
  File "/home/gerka/Desktop/kekMyPek/vol_bot/venv/lib/python3.11/site-packages/pandas/core/indexing.py", line 1685, in _validate_integer
    raise IndexError("single positional indexer is out-of-bounds")
IndexError: single positional indexer is out-of-bounds
2024-05-31 21:27:27,244 ERROR 
Traceback (most recent call last):
  File "/home/gerka/Desktop/kekMyPek/vol_bot/main.py", line 46, in main
    kLineDf = getKline(symbol, interval, Limit)
              ^^^^^^^^^^^^^^^^^^^^^^^^^^^^^^^^^
  File "/home/gerka/Desktop/kekMyPek/vol_bot/getData.py", line 21, in getKline
    rawReq = session.get_kline(
             ^^^^^^^^^^^^^^^^^^
  File "/home/gerka/Desktop/kekMyPek/vol_bot/venv/lib/python3.11/site-packages/pybit/_v5_market.py", line 33, in get_kline
    return self._submit_request(
           ^^^^^^^^^^^^^^^^^^^^^
  File "/home/gerka/Desktop/kekMyPek/vol_bot/venv/lib/python3.11/site-packages/pybit/_http_manager.py", line 379, in _submit_request
    raise InvalidRequestError(
pybit.exceptions.InvalidRequestError: The requested symbol is invalid. (ErrCode: 10001) (ErrTime: 16:27:27).
Request → GET https://api.bybit.com/v5/market/kline: category=linear&end=False&interval=60&limit=100&start=False&symbol=.
2024-05-31 21:28:03,053 ERROR 
Traceback (most recent call last):
  File "/home/gerka/Desktop/kekMyPek/vol_bot/main.py", line 46, in main
    kLineDf = getKline(symbol, interval, Limit)
              ^^^^^^^^^^^^^^^^^^^^^^^^^^^^^^^^^
  File "/home/gerka/Desktop/kekMyPek/vol_bot/getData.py", line 21, in getKline
    rawReq = session.get_kline(
             ^^^^^^^^^^^^^^^^^^
  File "/home/gerka/Desktop/kekMyPek/vol_bot/venv/lib/python3.11/site-packages/pybit/_v5_market.py", line 33, in get_kline
    return self._submit_request(
           ^^^^^^^^^^^^^^^^^^^^^
  File "/home/gerka/Desktop/kekMyPek/vol_bot/venv/lib/python3.11/site-packages/pybit/_http_manager.py", line 379, in _submit_request
    raise InvalidRequestError(
pybit.exceptions.InvalidRequestError: The requested symbol is invalid. (ErrCode: 10001) (ErrTime: 16:28:03).
Request → GET https://api.bybit.com/v5/market/kline: category=linear&end=False&interval=60&limit=100&start=False&symbol=.
2024-05-31 21:28:39,448 ERROR 
Traceback (most recent call last):
  File "/home/gerka/Desktop/kekMyPek/vol_bot/main.py", line 46, in main
    kLineDf = getKline(symbol, interval, Limit)
              ^^^^^^^^^^^^^^^^^^^^^^^^^^^^^^^^^
  File "/home/gerka/Desktop/kekMyPek/vol_bot/getData.py", line 21, in getKline
    rawReq = session.get_kline(
             ^^^^^^^^^^^^^^^^^^
  File "/home/gerka/Desktop/kekMyPek/vol_bot/venv/lib/python3.11/site-packages/pybit/_v5_market.py", line 33, in get_kline
    return self._submit_request(
           ^^^^^^^^^^^^^^^^^^^^^
  File "/home/gerka/Desktop/kekMyPek/vol_bot/venv/lib/python3.11/site-packages/pybit/_http_manager.py", line 379, in _submit_request
    raise InvalidRequestError(
pybit.exceptions.InvalidRequestError: The requested symbol is invalid. (ErrCode: 10001) (ErrTime: 16:28:39).
Request → GET https://api.bybit.com/v5/market/kline: category=linear&end=False&interval=60&limit=100&start=False&symbol=.
2024-05-31 21:30:57,489 ERROR 
Traceback (most recent call last):
  File "/home/gerka/Desktop/kekMyPek/vol_bot/main.py", line 48, in main
    kLineDf = getKline(symbol, interval, Limit)
              ^^^^^^^^^^^^^^^^^^^^^^^^^^^^^^^^^
  File "/home/gerka/Desktop/kekMyPek/vol_bot/getData.py", line 21, in getKline
    rawReq = session.get_kline(
             ^^^^^^^^^^^^^^^^^^
  File "/home/gerka/Desktop/kekMyPek/vol_bot/venv/lib/python3.11/site-packages/pybit/_v5_market.py", line 33, in get_kline
    return self._submit_request(
           ^^^^^^^^^^^^^^^^^^^^^
  File "/home/gerka/Desktop/kekMyPek/vol_bot/venv/lib/python3.11/site-packages/pybit/_http_manager.py", line 379, in _submit_request
    raise InvalidRequestError(
pybit.exceptions.InvalidRequestError: The requested symbol is invalid. (ErrCode: 10001) (ErrTime: 16:30:57).
Request → GET https://api.bybit.com/v5/market/kline: category=linear&end=False&interval=60&limit=100&start=False&symbol=.
2024-05-31 21:49:54,844 ERROR LTCUSDT
Traceback (most recent call last):
  File "/home/gerka/Desktop/kekMyPek/vol_bot/venv/lib/python3.11/site-packages/requests/models.py", line 974, in json
    return complexjson.loads(self.text, **kwargs)
           ^^^^^^^^^^^^^^^^^^^^^^^^^^^^^^^^^^^^^^
  File "/usr/lib/python3.11/json/__init__.py", line 346, in loads
    return _default_decoder.decode(s)
           ^^^^^^^^^^^^^^^^^^^^^^^^^^
  File "/usr/lib/python3.11/json/decoder.py", line 337, in decode
    obj, end = self.raw_decode(s, idx=_w(s, 0).end())
               ^^^^^^^^^^^^^^^^^^^^^^^^^^^^^^^^^^^^^^
  File "/usr/lib/python3.11/json/decoder.py", line 353, in raw_decode
    obj, end = self.scan_once(s, idx)
               ^^^^^^^^^^^^^^^^^^^^^^
json.decoder.JSONDecodeError: Expecting ',' delimiter: line 3 column 1 (char 446)

During handling of the above exception, another exception occurred:

Traceback (most recent call last):
  File "/home/gerka/Desktop/kekMyPek/vol_bot/venv/lib/python3.11/site-packages/pybit/_http_manager.py", line 316, in _submit_request
    s_json = s.json()
             ^^^^^^^^
  File "/home/gerka/Desktop/kekMyPek/vol_bot/venv/lib/python3.11/site-packages/requests/models.py", line 978, in json
    raise RequestsJSONDecodeError(e.msg, e.doc, e.pos)
requests.exceptions.JSONDecodeError: Expecting ',' delimiter: line 3 column 1 (char 446)

During handling of the above exception, another exception occurred:

Traceback (most recent call last):
  File "/home/gerka/Desktop/kekMyPek/vol_bot/main.py", line 48, in main
    kLineDf = getKline(symbol, interval, Limit)
              ^^^^^^^^^^^^^^^^^^^^^^^^^^^^^^^^^
  File "/home/gerka/Desktop/kekMyPek/vol_bot/getData.py", line 21, in getKline
    rawReq = session.get_kline(
             ^^^^^^^^^^^^^^^^^^
  File "/home/gerka/Desktop/kekMyPek/vol_bot/venv/lib/python3.11/site-packages/pybit/_v5_market.py", line 33, in get_kline
    return self._submit_request(
           ^^^^^^^^^^^^^^^^^^^^^
  File "/home/gerka/Desktop/kekMyPek/vol_bot/venv/lib/python3.11/site-packages/pybit/_http_manager.py", line 326, in _submit_request
    raise FailedRequestError(
pybit.exceptions.FailedRequestError: Conflict. could not decode json. (ErrCode: 409) (ErrTime: 16:49:54).
Request → GET https://api.bybit.com/v5/market/kline: category=linear&end=False&interval=60&limit=100&start=False&symbol=LTCUSDT.
