2024-05-31 13:42:46,344 ERROR main: 
Traceback (most recent call last):
  File "/home/gerka/Desktop/kekMyPek/vol_bot/venv/lib/python3.11/site-packages/urllib3/connection.py", line 198, in _new_conn
    sock = connection.create_connection(
           ^^^^^^^^^^^^^^^^^^^^^^^^^^^^^
  File "/home/gerka/Desktop/kekMyPek/vol_bot/venv/lib/python3.11/site-packages/urllib3/util/connection.py", line 60, in create_connection
    for res in socket.getaddrinfo(host, port, family, socket.SOCK_STREAM):
               ^^^^^^^^^^^^^^^^^^^^^^^^^^^^^^^^^^^^^^^^^^^^^^^^^^^^^^^^^^
  File "/usr/lib/python3.11/socket.py", line 962, in getaddrinfo
    for res in _socket.getaddrinfo(host, port, family, type, proto, flags):
               ^^^^^^^^^^^^^^^^^^^^^^^^^^^^^^^^^^^^^^^^^^^^^^^^^^^^^^^^^^^
socket.gaierror: [Errno -2] Name or service not known

The above exception was the direct cause of the following exception:

Traceback (most recent call last):
  File "/home/gerka/Desktop/kekMyPek/vol_bot/venv/lib/python3.11/site-packages/urllib3/connectionpool.py", line 793, in urlopen
    response = self._make_request(
               ^^^^^^^^^^^^^^^^^^^
  File "/home/gerka/Desktop/kekMyPek/vol_bot/venv/lib/python3.11/site-packages/urllib3/connectionpool.py", line 491, in _make_request
    raise new_e
  File "/home/gerka/Desktop/kekMyPek/vol_bot/venv/lib/python3.11/site-packages/urllib3/connectionpool.py", line 467, in _make_request
    self._validate_conn(conn)
  File "/home/gerka/Desktop/kekMyPek/vol_bot/venv/lib/python3.11/site-packages/urllib3/connectionpool.py", line 1099, in _validate_conn
    conn.connect()
  File "/home/gerka/Desktop/kekMyPek/vol_bot/venv/lib/python3.11/site-packages/urllib3/connection.py", line 616, in connect
    self.sock = sock = self._new_conn()
                       ^^^^^^^^^^^^^^^^
  File "/home/gerka/Desktop/kekMyPek/vol_bot/venv/lib/python3.11/site-packages/urllib3/connection.py", line 205, in _new_conn
    raise NameResolutionError(self.host, self, e) from e
urllib3.exceptions.NameResolutionError: <urllib3.connection.HTTPSConnection object at 0x7ff25186bb90>: Failed to resolve 'api.bybit.com' ([Errno -2] Name or service not known)

The above exception was the direct cause of the following exception:

Traceback (most recent call last):
  File "/home/gerka/Desktop/kekMyPek/vol_bot/venv/lib/python3.11/site-packages/requests/adapters.py", line 667, in send
    resp = conn.urlopen(
           ^^^^^^^^^^^^^
  File "/home/gerka/Desktop/kekMyPek/vol_bot/venv/lib/python3.11/site-packages/urllib3/connectionpool.py", line 847, in urlopen
    retries = retries.increment(
              ^^^^^^^^^^^^^^^^^^
  File "/home/gerka/Desktop/kekMyPek/vol_bot/venv/lib/python3.11/site-packages/urllib3/util/retry.py", line 515, in increment
    raise MaxRetryError(_pool, url, reason) from reason  # type: ignore[arg-type]
    ^^^^^^^^^^^^^^^^^^^^^^^^^^^^^^^^^^^^^^^^^^^^^^^^^^^
urllib3.exceptions.MaxRetryError: HTTPSConnectionPool(host='api.bybit.com', port=443): Max retries exceeded with url: /v5/market/kline?category=linear&end=False&interval=60&limit=500&start=False&symbol=1INCHUSDT (Caused by NameResolutionError("<urllib3.connection.HTTPSConnection object at 0x7ff25186bb90>: Failed to resolve 'api.bybit.com' ([Errno -2] Name or service not known)"))

During handling of the above exception, another exception occurred:

Traceback (most recent call last):
  File "/home/gerka/Desktop/kekMyPek/vol_bot/main.py", line 38, in main
    kLineDf = getKline(symbol, interval, Limit)
              ^^^^^^^^^^^^^^^^^^^^^^^^^^^^^^^^^
  File "/home/gerka/Desktop/kekMyPek/vol_bot/getData.py", line 21, in getKline
    rawReq = session.get_kline(
             ^^^^^^^^^^^^^^^^^^
  File "/home/gerka/Desktop/kekMyPek/vol_bot/venv/lib/python3.11/site-packages/pybit/_v5_market.py", line 33, in get_kline
    return self._submit_request(
           ^^^^^^^^^^^^^^^^^^^^^
  File "/home/gerka/Desktop/kekMyPek/vol_bot/venv/lib/python3.11/site-packages/pybit/_http_manager.py", line 297, in _submit_request
    raise e
  File "/home/gerka/Desktop/kekMyPek/vol_bot/venv/lib/python3.11/site-packages/pybit/_http_manager.py", line 284, in _submit_request
    s = self.client.send(r, timeout=self.timeout)
        ^^^^^^^^^^^^^^^^^^^^^^^^^^^^^^^^^^^^^^^^^
  File "/home/gerka/Desktop/kekMyPek/vol_bot/venv/lib/python3.11/site-packages/requests/sessions.py", line 703, in send
    r = adapter.send(request, **kwargs)
        ^^^^^^^^^^^^^^^^^^^^^^^^^^^^^^^
  File "/home/gerka/Desktop/kekMyPek/vol_bot/venv/lib/python3.11/site-packages/requests/adapters.py", line 700, in send
    raise ConnectionError(e, request=request)
requests.exceptions.ConnectionError: HTTPSConnectionPool(host='api.bybit.com', port=443): Max retries exceeded with url: /v5/market/kline?category=linear&end=False&interval=60&limit=500&start=False&symbol=1INCHUSDT (Caused by NameResolutionError("<urllib3.connection.HTTPSConnection object at 0x7ff25186bb90>: Failed to resolve 'api.bybit.com' ([Errno -2] Name or service not known)"))
2024-05-31 13:43:49,012 ERROR main: 
Traceback (most recent call last):
  File "/home/gerka/Desktop/kekMyPek/vol_bot/venv/lib/python3.11/site-packages/urllib3/connection.py", line 198, in _new_conn
    sock = connection.create_connection(
           ^^^^^^^^^^^^^^^^^^^^^^^^^^^^^
  File "/home/gerka/Desktop/kekMyPek/vol_bot/venv/lib/python3.11/site-packages/urllib3/util/connection.py", line 60, in create_connection
    for res in socket.getaddrinfo(host, port, family, socket.SOCK_STREAM):
               ^^^^^^^^^^^^^^^^^^^^^^^^^^^^^^^^^^^^^^^^^^^^^^^^^^^^^^^^^^
  File "/usr/lib/python3.11/socket.py", line 962, in getaddrinfo
    for res in _socket.getaddrinfo(host, port, family, type, proto, flags):
               ^^^^^^^^^^^^^^^^^^^^^^^^^^^^^^^^^^^^^^^^^^^^^^^^^^^^^^^^^^^
socket.gaierror: [Errno -2] Name or service not known

The above exception was the direct cause of the following exception:

Traceback (most recent call last):
  File "/home/gerka/Desktop/kekMyPek/vol_bot/venv/lib/python3.11/site-packages/urllib3/connectionpool.py", line 793, in urlopen
    response = self._make_request(
               ^^^^^^^^^^^^^^^^^^^
  File "/home/gerka/Desktop/kekMyPek/vol_bot/venv/lib/python3.11/site-packages/urllib3/connectionpool.py", line 491, in _make_request
    raise new_e
  File "/home/gerka/Desktop/kekMyPek/vol_bot/venv/lib/python3.11/site-packages/urllib3/connectionpool.py", line 467, in _make_request
    self._validate_conn(conn)
  File "/home/gerka/Desktop/kekMyPek/vol_bot/venv/lib/python3.11/site-packages/urllib3/connectionpool.py", line 1099, in _validate_conn
    conn.connect()
  File "/home/gerka/Desktop/kekMyPek/vol_bot/venv/lib/python3.11/site-packages/urllib3/connection.py", line 616, in connect
    self.sock = sock = self._new_conn()
                       ^^^^^^^^^^^^^^^^
  File "/home/gerka/Desktop/kekMyPek/vol_bot/venv/lib/python3.11/site-packages/urllib3/connection.py", line 205, in _new_conn
    raise NameResolutionError(self.host, self, e) from e
urllib3.exceptions.NameResolutionError: <urllib3.connection.HTTPSConnection object at 0x7ff1294b1b90>: Failed to resolve 'api.bybit.com' ([Errno -2] Name or service not known)

The above exception was the direct cause of the following exception:

Traceback (most recent call last):
  File "/home/gerka/Desktop/kekMyPek/vol_bot/venv/lib/python3.11/site-packages/requests/adapters.py", line 667, in send
    resp = conn.urlopen(
           ^^^^^^^^^^^^^
  File "/home/gerka/Desktop/kekMyPek/vol_bot/venv/lib/python3.11/site-packages/urllib3/connectionpool.py", line 847, in urlopen
    retries = retries.increment(
              ^^^^^^^^^^^^^^^^^^
  File "/home/gerka/Desktop/kekMyPek/vol_bot/venv/lib/python3.11/site-packages/urllib3/util/retry.py", line 515, in increment
    raise MaxRetryError(_pool, url, reason) from reason  # type: ignore[arg-type]
    ^^^^^^^^^^^^^^^^^^^^^^^^^^^^^^^^^^^^^^^^^^^^^^^^^^^
urllib3.exceptions.MaxRetryError: HTTPSConnectionPool(host='api.bybit.com', port=443): Max retries exceeded with url: /v5/market/kline?category=linear&end=False&interval=60&limit=500&start=False&symbol=1INCHUSDT (Caused by NameResolutionError("<urllib3.connection.HTTPSConnection object at 0x7ff1294b1b90>: Failed to resolve 'api.bybit.com' ([Errno -2] Name or service not known)"))

During handling of the above exception, another exception occurred:

Traceback (most recent call last):
  File "/home/gerka/Desktop/kekMyPek/vol_bot/main.py", line 38, in main
    kLineDf = getKline(symbol, interval, Limit)
              ^^^^^^^^^^^^^^^^^^^^^^^^^^^^^^^^^
  File "/home/gerka/Desktop/kekMyPek/vol_bot/getData.py", line 21, in getKline
    rawReq = session.get_kline(
             ^^^^^^^^^^^^^^^^^^
  File "/home/gerka/Desktop/kekMyPek/vol_bot/venv/lib/python3.11/site-packages/pybit/_v5_market.py", line 33, in get_kline
    return self._submit_request(
           ^^^^^^^^^^^^^^^^^^^^^
  File "/home/gerka/Desktop/kekMyPek/vol_bot/venv/lib/python3.11/site-packages/pybit/_http_manager.py", line 297, in _submit_request
    raise e
  File "/home/gerka/Desktop/kekMyPek/vol_bot/venv/lib/python3.11/site-packages/pybit/_http_manager.py", line 284, in _submit_request
    s = self.client.send(r, timeout=self.timeout)
        ^^^^^^^^^^^^^^^^^^^^^^^^^^^^^^^^^^^^^^^^^
  File "/home/gerka/Desktop/kekMyPek/vol_bot/venv/lib/python3.11/site-packages/requests/sessions.py", line 703, in send
    r = adapter.send(request, **kwargs)
        ^^^^^^^^^^^^^^^^^^^^^^^^^^^^^^^
  File "/home/gerka/Desktop/kekMyPek/vol_bot/venv/lib/python3.11/site-packages/requests/adapters.py", line 700, in send
    raise ConnectionError(e, request=request)
requests.exceptions.ConnectionError: HTTPSConnectionPool(host='api.bybit.com', port=443): Max retries exceeded with url: /v5/market/kline?category=linear&end=False&interval=60&limit=500&start=False&symbol=1INCHUSDT (Caused by NameResolutionError("<urllib3.connection.HTTPSConnection object at 0x7ff1294b1b90>: Failed to resolve 'api.bybit.com' ([Errno -2] Name or service not known)"))
2024-05-31 13:44:35,201 ERROR sendMessage: 
Traceback (most recent call last):
  File "/home/gerka/Desktop/kekMyPek/vol_bot/venv/lib/python3.11/site-packages/urllib3/connection.py", line 198, in _new_conn
    sock = connection.create_connection(
           ^^^^^^^^^^^^^^^^^^^^^^^^^^^^^
  File "/home/gerka/Desktop/kekMyPek/vol_bot/venv/lib/python3.11/site-packages/urllib3/util/connection.py", line 60, in create_connection
    for res in socket.getaddrinfo(host, port, family, socket.SOCK_STREAM):
               ^^^^^^^^^^^^^^^^^^^^^^^^^^^^^^^^^^^^^^^^^^^^^^^^^^^^^^^^^^
  File "/usr/lib/python3.11/socket.py", line 962, in getaddrinfo
    for res in _socket.getaddrinfo(host, port, family, type, proto, flags):
               ^^^^^^^^^^^^^^^^^^^^^^^^^^^^^^^^^^^^^^^^^^^^^^^^^^^^^^^^^^^
socket.gaierror: [Errno -2] Name or service not known

The above exception was the direct cause of the following exception:

Traceback (most recent call last):
  File "/home/gerka/Desktop/kekMyPek/vol_bot/venv/lib/python3.11/site-packages/urllib3/connectionpool.py", line 793, in urlopen
    response = self._make_request(
               ^^^^^^^^^^^^^^^^^^^
  File "/home/gerka/Desktop/kekMyPek/vol_bot/venv/lib/python3.11/site-packages/urllib3/connectionpool.py", line 491, in _make_request
    raise new_e
  File "/home/gerka/Desktop/kekMyPek/vol_bot/venv/lib/python3.11/site-packages/urllib3/connectionpool.py", line 467, in _make_request
    self._validate_conn(conn)
  File "/home/gerka/Desktop/kekMyPek/vol_bot/venv/lib/python3.11/site-packages/urllib3/connectionpool.py", line 1099, in _validate_conn
    conn.connect()
  File "/home/gerka/Desktop/kekMyPek/vol_bot/venv/lib/python3.11/site-packages/urllib3/connection.py", line 616, in connect
    self.sock = sock = self._new_conn()
                       ^^^^^^^^^^^^^^^^
  File "/home/gerka/Desktop/kekMyPek/vol_bot/venv/lib/python3.11/site-packages/urllib3/connection.py", line 205, in _new_conn
    raise NameResolutionError(self.host, self, e) from e
urllib3.exceptions.NameResolutionError: <urllib3.connection.HTTPSConnection object at 0x7ff1294b1b90>: Failed to resolve 'api.bybit.com' ([Errno -2] Name or service not known)

The above exception was the direct cause of the following exception:

Traceback (most recent call last):
  File "/home/gerka/Desktop/kekMyPek/vol_bot/venv/lib/python3.11/site-packages/requests/adapters.py", line 667, in send
    resp = conn.urlopen(
           ^^^^^^^^^^^^^
  File "/home/gerka/Desktop/kekMyPek/vol_bot/venv/lib/python3.11/site-packages/urllib3/connectionpool.py", line 847, in urlopen
    retries = retries.increment(
              ^^^^^^^^^^^^^^^^^^
  File "/home/gerka/Desktop/kekMyPek/vol_bot/venv/lib/python3.11/site-packages/urllib3/util/retry.py", line 515, in increment
    raise MaxRetryError(_pool, url, reason) from reason  # type: ignore[arg-type]
    ^^^^^^^^^^^^^^^^^^^^^^^^^^^^^^^^^^^^^^^^^^^^^^^^^^^
urllib3.exceptions.MaxRetryError: HTTPSConnectionPool(host='api.bybit.com', port=443): Max retries exceeded with url: /v5/market/kline?category=linear&end=False&interval=60&limit=500&start=False&symbol=1INCHUSDT (Caused by NameResolutionError("<urllib3.connection.HTTPSConnection object at 0x7ff1294b1b90>: Failed to resolve 'api.bybit.com' ([Errno -2] Name or service not known)"))

During handling of the above exception, another exception occurred:

Traceback (most recent call last):
  File "/home/gerka/Desktop/kekMyPek/vol_bot/main.py", line 38, in main
    kLineDf = getKline(symbol, interval, Limit)
              ^^^^^^^^^^^^^^^^^^^^^^^^^^^^^^^^^
  File "/home/gerka/Desktop/kekMyPek/vol_bot/getData.py", line 21, in getKline
    rawReq = session.get_kline(
             ^^^^^^^^^^^^^^^^^^
  File "/home/gerka/Desktop/kekMyPek/vol_bot/venv/lib/python3.11/site-packages/pybit/_v5_market.py", line 33, in get_kline
    return self._submit_request(
           ^^^^^^^^^^^^^^^^^^^^^
  File "/home/gerka/Desktop/kekMyPek/vol_bot/venv/lib/python3.11/site-packages/pybit/_http_manager.py", line 297, in _submit_request
    raise e
  File "/home/gerka/Desktop/kekMyPek/vol_bot/venv/lib/python3.11/site-packages/pybit/_http_manager.py", line 284, in _submit_request
    s = self.client.send(r, timeout=self.timeout)
        ^^^^^^^^^^^^^^^^^^^^^^^^^^^^^^^^^^^^^^^^^
  File "/home/gerka/Desktop/kekMyPek/vol_bot/venv/lib/python3.11/site-packages/requests/sessions.py", line 703, in send
    r = adapter.send(request, **kwargs)
        ^^^^^^^^^^^^^^^^^^^^^^^^^^^^^^^
  File "/home/gerka/Desktop/kekMyPek/vol_bot/venv/lib/python3.11/site-packages/requests/adapters.py", line 700, in send
    raise ConnectionError(e, request=request)
requests.exceptions.ConnectionError: HTTPSConnectionPool(host='api.bybit.com', port=443): Max retries exceeded with url: /v5/market/kline?category=linear&end=False&interval=60&limit=500&start=False&symbol=1INCHUSDT (Caused by NameResolutionError("<urllib3.connection.HTTPSConnection object at 0x7ff1294b1b90>: Failed to resolve 'api.bybit.com' ([Errno -2] Name or service not known)"))

During handling of the above exception, another exception occurred:

Traceback (most recent call last):
  File "/home/gerka/Desktop/kekMyPek/vol_bot/main.py", line 42, in main
    sendMessage(myID,symbol)
TypeError: sendMessage() takes 1 positional argument but 2 were given
2024-05-31 13:47:14,631 ERROR main: 
Traceback (most recent call last):
  File "/home/gerka/Desktop/kekMyPek/vol_bot/venv/lib/python3.11/site-packages/urllib3/connection.py", line 198, in _new_conn
    sock = connection.create_connection(
           ^^^^^^^^^^^^^^^^^^^^^^^^^^^^^
  File "/home/gerka/Desktop/kekMyPek/vol_bot/venv/lib/python3.11/site-packages/urllib3/util/connection.py", line 60, in create_connection
    for res in socket.getaddrinfo(host, port, family, socket.SOCK_STREAM):
               ^^^^^^^^^^^^^^^^^^^^^^^^^^^^^^^^^^^^^^^^^^^^^^^^^^^^^^^^^^
  File "/usr/lib/python3.11/socket.py", line 962, in getaddrinfo
    for res in _socket.getaddrinfo(host, port, family, type, proto, flags):
               ^^^^^^^^^^^^^^^^^^^^^^^^^^^^^^^^^^^^^^^^^^^^^^^^^^^^^^^^^^^
socket.gaierror: [Errno -2] Name or service not known

The above exception was the direct cause of the following exception:

Traceback (most recent call last):
  File "/home/gerka/Desktop/kekMyPek/vol_bot/venv/lib/python3.11/site-packages/urllib3/connectionpool.py", line 793, in urlopen
    response = self._make_request(
               ^^^^^^^^^^^^^^^^^^^
  File "/home/gerka/Desktop/kekMyPek/vol_bot/venv/lib/python3.11/site-packages/urllib3/connectionpool.py", line 491, in _make_request
    raise new_e
  File "/home/gerka/Desktop/kekMyPek/vol_bot/venv/lib/python3.11/site-packages/urllib3/connectionpool.py", line 467, in _make_request
    self._validate_conn(conn)
  File "/home/gerka/Desktop/kekMyPek/vol_bot/venv/lib/python3.11/site-packages/urllib3/connectionpool.py", line 1099, in _validate_conn
    conn.connect()
  File "/home/gerka/Desktop/kekMyPek/vol_bot/venv/lib/python3.11/site-packages/urllib3/connection.py", line 616, in connect
    self.sock = sock = self._new_conn()
                       ^^^^^^^^^^^^^^^^
  File "/home/gerka/Desktop/kekMyPek/vol_bot/venv/lib/python3.11/site-packages/urllib3/connection.py", line 205, in _new_conn
    raise NameResolutionError(self.host, self, e) from e
urllib3.exceptions.NameResolutionError: <urllib3.connection.HTTPSConnection object at 0x7f5371f8ea10>: Failed to resolve 'api.bybit.com' ([Errno -2] Name or service not known)

The above exception was the direct cause of the following exception:

Traceback (most recent call last):
  File "/home/gerka/Desktop/kekMyPek/vol_bot/venv/lib/python3.11/site-packages/requests/adapters.py", line 667, in send
    resp = conn.urlopen(
           ^^^^^^^^^^^^^
  File "/home/gerka/Desktop/kekMyPek/vol_bot/venv/lib/python3.11/site-packages/urllib3/connectionpool.py", line 847, in urlopen
    retries = retries.increment(
              ^^^^^^^^^^^^^^^^^^
  File "/home/gerka/Desktop/kekMyPek/vol_bot/venv/lib/python3.11/site-packages/urllib3/util/retry.py", line 515, in increment
    raise MaxRetryError(_pool, url, reason) from reason  # type: ignore[arg-type]
    ^^^^^^^^^^^^^^^^^^^^^^^^^^^^^^^^^^^^^^^^^^^^^^^^^^^
urllib3.exceptions.MaxRetryError: HTTPSConnectionPool(host='api.bybit.com', port=443): Max retries exceeded with url: /v5/market/kline?category=linear&end=False&interval=60&limit=500&start=False&symbol=1INCHUSDT (Caused by NameResolutionError("<urllib3.connection.HTTPSConnection object at 0x7f5371f8ea10>: Failed to resolve 'api.bybit.com' ([Errno -2] Name or service not known)"))

During handling of the above exception, another exception occurred:

Traceback (most recent call last):
  File "/home/gerka/Desktop/kekMyPek/vol_bot/main.py", line 38, in main
    kLineDf = getKline(symbol, interval, Limit)
              ^^^^^^^^^^^^^^^^^^^^^^^^^^^^^^^^^
  File "/home/gerka/Desktop/kekMyPek/vol_bot/getData.py", line 21, in getKline
    rawReq = session.get_kline(
             ^^^^^^^^^^^^^^^^^^
  File "/home/gerka/Desktop/kekMyPek/vol_bot/venv/lib/python3.11/site-packages/pybit/_v5_market.py", line 33, in get_kline
    return self._submit_request(
           ^^^^^^^^^^^^^^^^^^^^^
  File "/home/gerka/Desktop/kekMyPek/vol_bot/venv/lib/python3.11/site-packages/pybit/_http_manager.py", line 297, in _submit_request
    raise e
  File "/home/gerka/Desktop/kekMyPek/vol_bot/venv/lib/python3.11/site-packages/pybit/_http_manager.py", line 284, in _submit_request
    s = self.client.send(r, timeout=self.timeout)
        ^^^^^^^^^^^^^^^^^^^^^^^^^^^^^^^^^^^^^^^^^
  File "/home/gerka/Desktop/kekMyPek/vol_bot/venv/lib/python3.11/site-packages/requests/sessions.py", line 703, in send
    r = adapter.send(request, **kwargs)
        ^^^^^^^^^^^^^^^^^^^^^^^^^^^^^^^
  File "/home/gerka/Desktop/kekMyPek/vol_bot/venv/lib/python3.11/site-packages/requests/adapters.py", line 700, in send
    raise ConnectionError(e, request=request)
requests.exceptions.ConnectionError: HTTPSConnectionPool(host='api.bybit.com', port=443): Max retries exceeded with url: /v5/market/kline?category=linear&end=False&interval=60&limit=500&start=False&symbol=1INCHUSDT (Caused by NameResolutionError("<urllib3.connection.HTTPSConnection object at 0x7f5371f8ea10>: Failed to resolve 'api.bybit.com' ([Errno -2] Name or service not known)"))
2024-05-31 13:48:01,018 ERROR main: 
Traceback (most recent call last):
  File "/home/gerka/Desktop/kekMyPek/vol_bot/venv/lib/python3.11/site-packages/urllib3/connection.py", line 198, in _new_conn
    sock = connection.create_connection(
           ^^^^^^^^^^^^^^^^^^^^^^^^^^^^^
  File "/home/gerka/Desktop/kekMyPek/vol_bot/venv/lib/python3.11/site-packages/urllib3/util/connection.py", line 60, in create_connection
    for res in socket.getaddrinfo(host, port, family, socket.SOCK_STREAM):
               ^^^^^^^^^^^^^^^^^^^^^^^^^^^^^^^^^^^^^^^^^^^^^^^^^^^^^^^^^^
  File "/usr/lib/python3.11/socket.py", line 962, in getaddrinfo
    for res in _socket.getaddrinfo(host, port, family, type, proto, flags):
               ^^^^^^^^^^^^^^^^^^^^^^^^^^^^^^^^^^^^^^^^^^^^^^^^^^^^^^^^^^^
socket.gaierror: [Errno -2] Name or service not known

The above exception was the direct cause of the following exception:

Traceback (most recent call last):
  File "/home/gerka/Desktop/kekMyPek/vol_bot/venv/lib/python3.11/site-packages/urllib3/connectionpool.py", line 793, in urlopen
    response = self._make_request(
               ^^^^^^^^^^^^^^^^^^^
  File "/home/gerka/Desktop/kekMyPek/vol_bot/venv/lib/python3.11/site-packages/urllib3/connectionpool.py", line 491, in _make_request
    raise new_e
  File "/home/gerka/Desktop/kekMyPek/vol_bot/venv/lib/python3.11/site-packages/urllib3/connectionpool.py", line 467, in _make_request
    self._validate_conn(conn)
  File "/home/gerka/Desktop/kekMyPek/vol_bot/venv/lib/python3.11/site-packages/urllib3/connectionpool.py", line 1099, in _validate_conn
    conn.connect()
  File "/home/gerka/Desktop/kekMyPek/vol_bot/venv/lib/python3.11/site-packages/urllib3/connection.py", line 616, in connect
    self.sock = sock = self._new_conn()
                       ^^^^^^^^^^^^^^^^
  File "/home/gerka/Desktop/kekMyPek/vol_bot/venv/lib/python3.11/site-packages/urllib3/connection.py", line 205, in _new_conn
    raise NameResolutionError(self.host, self, e) from e
urllib3.exceptions.NameResolutionError: <urllib3.connection.HTTPSConnection object at 0x7f5371f8ea10>: Failed to resolve 'api.bybit.com' ([Errno -2] Name or service not known)

The above exception was the direct cause of the following exception:

Traceback (most recent call last):
  File "/home/gerka/Desktop/kekMyPek/vol_bot/venv/lib/python3.11/site-packages/requests/adapters.py", line 667, in send
    resp = conn.urlopen(
           ^^^^^^^^^^^^^
  File "/home/gerka/Desktop/kekMyPek/vol_bot/venv/lib/python3.11/site-packages/urllib3/connectionpool.py", line 847, in urlopen
    retries = retries.increment(
              ^^^^^^^^^^^^^^^^^^
  File "/home/gerka/Desktop/kekMyPek/vol_bot/venv/lib/python3.11/site-packages/urllib3/util/retry.py", line 515, in increment
    raise MaxRetryError(_pool, url, reason) from reason  # type: ignore[arg-type]
    ^^^^^^^^^^^^^^^^^^^^^^^^^^^^^^^^^^^^^^^^^^^^^^^^^^^
urllib3.exceptions.MaxRetryError: HTTPSConnectionPool(host='api.bybit.com', port=443): Max retries exceeded with url: /v5/market/kline?category=linear&end=False&interval=60&limit=500&start=False&symbol=1INCHUSDT (Caused by NameResolutionError("<urllib3.connection.HTTPSConnection object at 0x7f5371f8ea10>: Failed to resolve 'api.bybit.com' ([Errno -2] Name or service not known)"))

During handling of the above exception, another exception occurred:

Traceback (most recent call last):
  File "/home/gerka/Desktop/kekMyPek/vol_bot/main.py", line 38, in main
    kLineDf = getKline(symbol, interval, Limit)
              ^^^^^^^^^^^^^^^^^^^^^^^^^^^^^^^^^
  File "/home/gerka/Desktop/kekMyPek/vol_bot/getData.py", line 21, in getKline
    rawReq = session.get_kline(
             ^^^^^^^^^^^^^^^^^^
  File "/home/gerka/Desktop/kekMyPek/vol_bot/venv/lib/python3.11/site-packages/pybit/_v5_market.py", line 33, in get_kline
    return self._submit_request(
           ^^^^^^^^^^^^^^^^^^^^^
  File "/home/gerka/Desktop/kekMyPek/vol_bot/venv/lib/python3.11/site-packages/pybit/_http_manager.py", line 297, in _submit_request
    raise e
  File "/home/gerka/Desktop/kekMyPek/vol_bot/venv/lib/python3.11/site-packages/pybit/_http_manager.py", line 284, in _submit_request
    s = self.client.send(r, timeout=self.timeout)
        ^^^^^^^^^^^^^^^^^^^^^^^^^^^^^^^^^^^^^^^^^
  File "/home/gerka/Desktop/kekMyPek/vol_bot/venv/lib/python3.11/site-packages/requests/sessions.py", line 703, in send
    r = adapter.send(request, **kwargs)
        ^^^^^^^^^^^^^^^^^^^^^^^^^^^^^^^
  File "/home/gerka/Desktop/kekMyPek/vol_bot/venv/lib/python3.11/site-packages/requests/adapters.py", line 700, in send
    raise ConnectionError(e, request=request)
requests.exceptions.ConnectionError: HTTPSConnectionPool(host='api.bybit.com', port=443): Max retries exceeded with url: /v5/market/kline?category=linear&end=False&interval=60&limit=500&start=False&symbol=1INCHUSDT (Caused by NameResolutionError("<urllib3.connection.HTTPSConnection object at 0x7f5371f8ea10>: Failed to resolve 'api.bybit.com' ([Errno -2] Name or service not known)"))

During handling of the above exception, another exception occurred:

Traceback (most recent call last):
  File "/home/gerka/Desktop/kekMyPek/vol_bot/venv/lib/python3.11/site-packages/urllib3/connection.py", line 198, in _new_conn
    sock = connection.create_connection(
           ^^^^^^^^^^^^^^^^^^^^^^^^^^^^^
  File "/home/gerka/Desktop/kekMyPek/vol_bot/venv/lib/python3.11/site-packages/urllib3/util/connection.py", line 60, in create_connection
    for res in socket.getaddrinfo(host, port, family, socket.SOCK_STREAM):
               ^^^^^^^^^^^^^^^^^^^^^^^^^^^^^^^^^^^^^^^^^^^^^^^^^^^^^^^^^^
  File "/usr/lib/python3.11/socket.py", line 962, in getaddrinfo
    for res in _socket.getaddrinfo(host, port, family, type, proto, flags):
               ^^^^^^^^^^^^^^^^^^^^^^^^^^^^^^^^^^^^^^^^^^^^^^^^^^^^^^^^^^^
socket.gaierror: [Errno -2] Name or service not known

The above exception was the direct cause of the following exception:

Traceback (most recent call last):
  File "/home/gerka/Desktop/kekMyPek/vol_bot/venv/lib/python3.11/site-packages/urllib3/connectionpool.py", line 793, in urlopen
    response = self._make_request(
               ^^^^^^^^^^^^^^^^^^^
  File "/home/gerka/Desktop/kekMyPek/vol_bot/venv/lib/python3.11/site-packages/urllib3/connectionpool.py", line 491, in _make_request
    raise new_e
  File "/home/gerka/Desktop/kekMyPek/vol_bot/venv/lib/python3.11/site-packages/urllib3/connectionpool.py", line 467, in _make_request
    self._validate_conn(conn)
  File "/home/gerka/Desktop/kekMyPek/vol_bot/venv/lib/python3.11/site-packages/urllib3/connectionpool.py", line 1099, in _validate_conn
    conn.connect()
  File "/home/gerka/Desktop/kekMyPek/vol_bot/venv/lib/python3.11/site-packages/urllib3/connection.py", line 616, in connect
    self.sock = sock = self._new_conn()
                       ^^^^^^^^^^^^^^^^
  File "/home/gerka/Desktop/kekMyPek/vol_bot/venv/lib/python3.11/site-packages/urllib3/connection.py", line 205, in _new_conn
    raise NameResolutionError(self.host, self, e) from e
urllib3.exceptions.NameResolutionError: <urllib3.connection.HTTPSConnection object at 0x7f536f627c90>: Failed to resolve 'api.bybit.com' ([Errno -2] Name or service not known)

The above exception was the direct cause of the following exception:

Traceback (most recent call last):
  File "/home/gerka/Desktop/kekMyPek/vol_bot/venv/lib/python3.11/site-packages/requests/adapters.py", line 667, in send
    resp = conn.urlopen(
           ^^^^^^^^^^^^^
  File "/home/gerka/Desktop/kekMyPek/vol_bot/venv/lib/python3.11/site-packages/urllib3/connectionpool.py", line 847, in urlopen
    retries = retries.increment(
              ^^^^^^^^^^^^^^^^^^
  File "/home/gerka/Desktop/kekMyPek/vol_bot/venv/lib/python3.11/site-packages/urllib3/util/retry.py", line 515, in increment
    raise MaxRetryError(_pool, url, reason) from reason  # type: ignore[arg-type]
    ^^^^^^^^^^^^^^^^^^^^^^^^^^^^^^^^^^^^^^^^^^^^^^^^^^^
urllib3.exceptions.MaxRetryError: HTTPSConnectionPool(host='api.bybit.com', port=443): Max retries exceeded with url: /v5/market/kline?category=linear&end=False&interval=60&limit=500&start=False&symbol=1INCHUSDT (Caused by NameResolutionError("<urllib3.connection.HTTPSConnection object at 0x7f536f627c90>: Failed to resolve 'api.bybit.com' ([Errno -2] Name or service not known)"))

During handling of the above exception, another exception occurred:

Traceback (most recent call last):
  File "/home/gerka/Desktop/kekMyPek/vol_bot/main.py", line 38, in main
    kLineDf = getKline(symbol, interval, Limit)
              ^^^^^^^^^^^^^^^^^^^^^^^^^^^^^^^^^
  File "/home/gerka/Desktop/kekMyPek/vol_bot/getData.py", line 21, in getKline
    rawReq = session.get_kline(
             ^^^^^^^^^^^^^^^^^^
  File "/home/gerka/Desktop/kekMyPek/vol_bot/venv/lib/python3.11/site-packages/pybit/_v5_market.py", line 33, in get_kline
    return self._submit_request(
           ^^^^^^^^^^^^^^^^^^^^^
  File "/home/gerka/Desktop/kekMyPek/vol_bot/venv/lib/python3.11/site-packages/pybit/_http_manager.py", line 297, in _submit_request
    raise e
  File "/home/gerka/Desktop/kekMyPek/vol_bot/venv/lib/python3.11/site-packages/pybit/_http_manager.py", line 284, in _submit_request
    s = self.client.send(r, timeout=self.timeout)
        ^^^^^^^^^^^^^^^^^^^^^^^^^^^^^^^^^^^^^^^^^
  File "/home/gerka/Desktop/kekMyPek/vol_bot/venv/lib/python3.11/site-packages/requests/sessions.py", line 703, in send
    r = adapter.send(request, **kwargs)
        ^^^^^^^^^^^^^^^^^^^^^^^^^^^^^^^
  File "/home/gerka/Desktop/kekMyPek/vol_bot/venv/lib/python3.11/site-packages/requests/adapters.py", line 700, in send
    raise ConnectionError(e, request=request)
requests.exceptions.ConnectionError: HTTPSConnectionPool(host='api.bybit.com', port=443): Max retries exceeded with url: /v5/market/kline?category=linear&end=False&interval=60&limit=500&start=False&symbol=1INCHUSDT (Caused by NameResolutionError("<urllib3.connection.HTTPSConnection object at 0x7f536f627c90>: Failed to resolve 'api.bybit.com' ([Errno -2] Name or service not known)"))
2024-05-31 13:48:06,655 ERROR main: 
Traceback (most recent call last):
  File "/home/gerka/Desktop/kekMyPek/vol_bot/venv/lib/python3.11/site-packages/urllib3/connection.py", line 198, in _new_conn
    sock = connection.create_connection(
           ^^^^^^^^^^^^^^^^^^^^^^^^^^^^^
  File "/home/gerka/Desktop/kekMyPek/vol_bot/venv/lib/python3.11/site-packages/urllib3/util/connection.py", line 60, in create_connection
    for res in socket.getaddrinfo(host, port, family, socket.SOCK_STREAM):
               ^^^^^^^^^^^^^^^^^^^^^^^^^^^^^^^^^^^^^^^^^^^^^^^^^^^^^^^^^^
  File "/usr/lib/python3.11/socket.py", line 962, in getaddrinfo
    for res in _socket.getaddrinfo(host, port, family, type, proto, flags):
               ^^^^^^^^^^^^^^^^^^^^^^^^^^^^^^^^^^^^^^^^^^^^^^^^^^^^^^^^^^^
socket.gaierror: [Errno -2] Name or service not known

The above exception was the direct cause of the following exception:

Traceback (most recent call last):
  File "/home/gerka/Desktop/kekMyPek/vol_bot/venv/lib/python3.11/site-packages/urllib3/connectionpool.py", line 793, in urlopen
    response = self._make_request(
               ^^^^^^^^^^^^^^^^^^^
  File "/home/gerka/Desktop/kekMyPek/vol_bot/venv/lib/python3.11/site-packages/urllib3/connectionpool.py", line 491, in _make_request
    raise new_e
  File "/home/gerka/Desktop/kekMyPek/vol_bot/venv/lib/python3.11/site-packages/urllib3/connectionpool.py", line 467, in _make_request
    self._validate_conn(conn)
  File "/home/gerka/Desktop/kekMyPek/vol_bot/venv/lib/python3.11/site-packages/urllib3/connectionpool.py", line 1099, in _validate_conn
    conn.connect()
  File "/home/gerka/Desktop/kekMyPek/vol_bot/venv/lib/python3.11/site-packages/urllib3/connection.py", line 616, in connect
    self.sock = sock = self._new_conn()
                       ^^^^^^^^^^^^^^^^
  File "/home/gerka/Desktop/kekMyPek/vol_bot/venv/lib/python3.11/site-packages/urllib3/connection.py", line 205, in _new_conn
    raise NameResolutionError(self.host, self, e) from e
urllib3.exceptions.NameResolutionError: <urllib3.connection.HTTPSConnection object at 0x7f5371f8ea10>: Failed to resolve 'api.bybit.com' ([Errno -2] Name or service not known)

The above exception was the direct cause of the following exception:

Traceback (most recent call last):
  File "/home/gerka/Desktop/kekMyPek/vol_bot/venv/lib/python3.11/site-packages/requests/adapters.py", line 667, in send
    resp = conn.urlopen(
           ^^^^^^^^^^^^^
  File "/home/gerka/Desktop/kekMyPek/vol_bot/venv/lib/python3.11/site-packages/urllib3/connectionpool.py", line 847, in urlopen
    retries = retries.increment(
              ^^^^^^^^^^^^^^^^^^
  File "/home/gerka/Desktop/kekMyPek/vol_bot/venv/lib/python3.11/site-packages/urllib3/util/retry.py", line 515, in increment
    raise MaxRetryError(_pool, url, reason) from reason  # type: ignore[arg-type]
    ^^^^^^^^^^^^^^^^^^^^^^^^^^^^^^^^^^^^^^^^^^^^^^^^^^^
urllib3.exceptions.MaxRetryError: HTTPSConnectionPool(host='api.bybit.com', port=443): Max retries exceeded with url: /v5/market/kline?category=linear&end=False&interval=60&limit=500&start=False&symbol=1INCHUSDT (Caused by NameResolutionError("<urllib3.connection.HTTPSConnection object at 0x7f5371f8ea10>: Failed to resolve 'api.bybit.com' ([Errno -2] Name or service not known)"))

During handling of the above exception, another exception occurred:

Traceback (most recent call last):
  File "/home/gerka/Desktop/kekMyPek/vol_bot/main.py", line 38, in main
    kLineDf = getKline(symbol, interval, Limit)
              ^^^^^^^^^^^^^^^^^^^^^^^^^^^^^^^^^
  File "/home/gerka/Desktop/kekMyPek/vol_bot/getData.py", line 21, in getKline
    rawReq = session.get_kline(
             ^^^^^^^^^^^^^^^^^^
  File "/home/gerka/Desktop/kekMyPek/vol_bot/venv/lib/python3.11/site-packages/pybit/_v5_market.py", line 33, in get_kline
    return self._submit_request(
           ^^^^^^^^^^^^^^^^^^^^^
  File "/home/gerka/Desktop/kekMyPek/vol_bot/venv/lib/python3.11/site-packages/pybit/_http_manager.py", line 297, in _submit_request
    raise e
  File "/home/gerka/Desktop/kekMyPek/vol_bot/venv/lib/python3.11/site-packages/pybit/_http_manager.py", line 284, in _submit_request
    s = self.client.send(r, timeout=self.timeout)
        ^^^^^^^^^^^^^^^^^^^^^^^^^^^^^^^^^^^^^^^^^
  File "/home/gerka/Desktop/kekMyPek/vol_bot/venv/lib/python3.11/site-packages/requests/sessions.py", line 703, in send
    r = adapter.send(request, **kwargs)
        ^^^^^^^^^^^^^^^^^^^^^^^^^^^^^^^
  File "/home/gerka/Desktop/kekMyPek/vol_bot/venv/lib/python3.11/site-packages/requests/adapters.py", line 700, in send
    raise ConnectionError(e, request=request)
requests.exceptions.ConnectionError: HTTPSConnectionPool(host='api.bybit.com', port=443): Max retries exceeded with url: /v5/market/kline?category=linear&end=False&interval=60&limit=500&start=False&symbol=1INCHUSDT (Caused by NameResolutionError("<urllib3.connection.HTTPSConnection object at 0x7f5371f8ea10>: Failed to resolve 'api.bybit.com' ([Errno -2] Name or service not known)"))

During handling of the above exception, another exception occurred:

Traceback (most recent call last):
  File "/home/gerka/Desktop/kekMyPek/vol_bot/venv/lib/python3.11/site-packages/urllib3/connection.py", line 198, in _new_conn
    sock = connection.create_connection(
           ^^^^^^^^^^^^^^^^^^^^^^^^^^^^^
  File "/home/gerka/Desktop/kekMyPek/vol_bot/venv/lib/python3.11/site-packages/urllib3/util/connection.py", line 60, in create_connection
    for res in socket.getaddrinfo(host, port, family, socket.SOCK_STREAM):
               ^^^^^^^^^^^^^^^^^^^^^^^^^^^^^^^^^^^^^^^^^^^^^^^^^^^^^^^^^^
  File "/usr/lib/python3.11/socket.py", line 962, in getaddrinfo
    for res in _socket.getaddrinfo(host, port, family, type, proto, flags):
               ^^^^^^^^^^^^^^^^^^^^^^^^^^^^^^^^^^^^^^^^^^^^^^^^^^^^^^^^^^^
socket.gaierror: [Errno -2] Name or service not known

The above exception was the direct cause of the following exception:

Traceback (most recent call last):
  File "/home/gerka/Desktop/kekMyPek/vol_bot/venv/lib/python3.11/site-packages/urllib3/connectionpool.py", line 793, in urlopen
    response = self._make_request(
               ^^^^^^^^^^^^^^^^^^^
  File "/home/gerka/Desktop/kekMyPek/vol_bot/venv/lib/python3.11/site-packages/urllib3/connectionpool.py", line 491, in _make_request
    raise new_e
  File "/home/gerka/Desktop/kekMyPek/vol_bot/venv/lib/python3.11/site-packages/urllib3/connectionpool.py", line 467, in _make_request
    self._validate_conn(conn)
  File "/home/gerka/Desktop/kekMyPek/vol_bot/venv/lib/python3.11/site-packages/urllib3/connectionpool.py", line 1099, in _validate_conn
    conn.connect()
  File "/home/gerka/Desktop/kekMyPek/vol_bot/venv/lib/python3.11/site-packages/urllib3/connection.py", line 616, in connect
    self.sock = sock = self._new_conn()
                       ^^^^^^^^^^^^^^^^
  File "/home/gerka/Desktop/kekMyPek/vol_bot/venv/lib/python3.11/site-packages/urllib3/connection.py", line 205, in _new_conn
    raise NameResolutionError(self.host, self, e) from e
urllib3.exceptions.NameResolutionError: <urllib3.connection.HTTPSConnection object at 0x7f536f627c90>: Failed to resolve 'api.bybit.com' ([Errno -2] Name or service not known)

The above exception was the direct cause of the following exception:

Traceback (most recent call last):
  File "/home/gerka/Desktop/kekMyPek/vol_bot/venv/lib/python3.11/site-packages/requests/adapters.py", line 667, in send
    resp = conn.urlopen(
           ^^^^^^^^^^^^^
  File "/home/gerka/Desktop/kekMyPek/vol_bot/venv/lib/python3.11/site-packages/urllib3/connectionpool.py", line 847, in urlopen
    retries = retries.increment(
              ^^^^^^^^^^^^^^^^^^
  File "/home/gerka/Desktop/kekMyPek/vol_bot/venv/lib/python3.11/site-packages/urllib3/util/retry.py", line 515, in increment
    raise MaxRetryError(_pool, url, reason) from reason  # type: ignore[arg-type]
    ^^^^^^^^^^^^^^^^^^^^^^^^^^^^^^^^^^^^^^^^^^^^^^^^^^^
urllib3.exceptions.MaxRetryError: HTTPSConnectionPool(host='api.bybit.com', port=443): Max retries exceeded with url: /v5/market/kline?category=linear&end=False&interval=60&limit=500&start=False&symbol=1INCHUSDT (Caused by NameResolutionError("<urllib3.connection.HTTPSConnection object at 0x7f536f627c90>: Failed to resolve 'api.bybit.com' ([Errno -2] Name or service not known)"))

During handling of the above exception, another exception occurred:

Traceback (most recent call last):
  File "/home/gerka/Desktop/kekMyPek/vol_bot/main.py", line 38, in main
    kLineDf = getKline(symbol, interval, Limit)
              ^^^^^^^^^^^^^^^^^^^^^^^^^^^^^^^^^
  File "/home/gerka/Desktop/kekMyPek/vol_bot/getData.py", line 21, in getKline
    rawReq = session.get_kline(
             ^^^^^^^^^^^^^^^^^^
  File "/home/gerka/Desktop/kekMyPek/vol_bot/venv/lib/python3.11/site-packages/pybit/_v5_market.py", line 33, in get_kline
    return self._submit_request(
           ^^^^^^^^^^^^^^^^^^^^^
  File "/home/gerka/Desktop/kekMyPek/vol_bot/venv/lib/python3.11/site-packages/pybit/_http_manager.py", line 297, in _submit_request
    raise e
  File "/home/gerka/Desktop/kekMyPek/vol_bot/venv/lib/python3.11/site-packages/pybit/_http_manager.py", line 284, in _submit_request
    s = self.client.send(r, timeout=self.timeout)
        ^^^^^^^^^^^^^^^^^^^^^^^^^^^^^^^^^^^^^^^^^
  File "/home/gerka/Desktop/kekMyPek/vol_bot/venv/lib/python3.11/site-packages/requests/sessions.py", line 703, in send
    r = adapter.send(request, **kwargs)
        ^^^^^^^^^^^^^^^^^^^^^^^^^^^^^^^
  File "/home/gerka/Desktop/kekMyPek/vol_bot/venv/lib/python3.11/site-packages/requests/adapters.py", line 700, in send
    raise ConnectionError(e, request=request)
requests.exceptions.ConnectionError: HTTPSConnectionPool(host='api.bybit.com', port=443): Max retries exceeded with url: /v5/market/kline?category=linear&end=False&interval=60&limit=500&start=False&symbol=1INCHUSDT (Caused by NameResolutionError("<urllib3.connection.HTTPSConnection object at 0x7f536f627c90>: Failed to resolve 'api.bybit.com' ([Errno -2] Name or service not known)"))

During handling of the above exception, another exception occurred:

Traceback (most recent call last):
  File "/home/gerka/Desktop/kekMyPek/vol_bot/venv/lib/python3.11/site-packages/urllib3/connection.py", line 198, in _new_conn
    sock = connection.create_connection(
           ^^^^^^^^^^^^^^^^^^^^^^^^^^^^^
  File "/home/gerka/Desktop/kekMyPek/vol_bot/venv/lib/python3.11/site-packages/urllib3/util/connection.py", line 60, in create_connection
    for res in socket.getaddrinfo(host, port, family, socket.SOCK_STREAM):
               ^^^^^^^^^^^^^^^^^^^^^^^^^^^^^^^^^^^^^^^^^^^^^^^^^^^^^^^^^^
  File "/usr/lib/python3.11/socket.py", line 962, in getaddrinfo
    for res in _socket.getaddrinfo(host, port, family, type, proto, flags):
               ^^^^^^^^^^^^^^^^^^^^^^^^^^^^^^^^^^^^^^^^^^^^^^^^^^^^^^^^^^^
socket.gaierror: [Errno -2] Name or service not known

The above exception was the direct cause of the following exception:

Traceback (most recent call last):
  File "/home/gerka/Desktop/kekMyPek/vol_bot/venv/lib/python3.11/site-packages/urllib3/connectionpool.py", line 793, in urlopen
    response = self._make_request(
               ^^^^^^^^^^^^^^^^^^^
  File "/home/gerka/Desktop/kekMyPek/vol_bot/venv/lib/python3.11/site-packages/urllib3/connectionpool.py", line 491, in _make_request
    raise new_e
  File "/home/gerka/Desktop/kekMyPek/vol_bot/venv/lib/python3.11/site-packages/urllib3/connectionpool.py", line 467, in _make_request
    self._validate_conn(conn)
  File "/home/gerka/Desktop/kekMyPek/vol_bot/venv/lib/python3.11/site-packages/urllib3/connectionpool.py", line 1099, in _validate_conn
    conn.connect()
  File "/home/gerka/Desktop/kekMyPek/vol_bot/venv/lib/python3.11/site-packages/urllib3/connection.py", line 616, in connect
    self.sock = sock = self._new_conn()
                       ^^^^^^^^^^^^^^^^
  File "/home/gerka/Desktop/kekMyPek/vol_bot/venv/lib/python3.11/site-packages/urllib3/connection.py", line 205, in _new_conn
    raise NameResolutionError(self.host, self, e) from e
urllib3.exceptions.NameResolutionError: <urllib3.connection.HTTPSConnection object at 0x7f536f3f1c50>: Failed to resolve 'api.bybit.com' ([Errno -2] Name or service not known)

The above exception was the direct cause of the following exception:

Traceback (most recent call last):
  File "/home/gerka/Desktop/kekMyPek/vol_bot/venv/lib/python3.11/site-packages/requests/adapters.py", line 667, in send
    resp = conn.urlopen(
           ^^^^^^^^^^^^^
  File "/home/gerka/Desktop/kekMyPek/vol_bot/venv/lib/python3.11/site-packages/urllib3/connectionpool.py", line 847, in urlopen
    retries = retries.increment(
              ^^^^^^^^^^^^^^^^^^
  File "/home/gerka/Desktop/kekMyPek/vol_bot/venv/lib/python3.11/site-packages/urllib3/util/retry.py", line 515, in increment
    raise MaxRetryError(_pool, url, reason) from reason  # type: ignore[arg-type]
    ^^^^^^^^^^^^^^^^^^^^^^^^^^^^^^^^^^^^^^^^^^^^^^^^^^^
urllib3.exceptions.MaxRetryError: HTTPSConnectionPool(host='api.bybit.com', port=443): Max retries exceeded with url: /v5/market/kline?category=linear&end=False&interval=60&limit=500&start=False&symbol=1INCHUSDT (Caused by NameResolutionError("<urllib3.connection.HTTPSConnection object at 0x7f536f3f1c50>: Failed to resolve 'api.bybit.com' ([Errno -2] Name or service not known)"))

During handling of the above exception, another exception occurred:

Traceback (most recent call last):
  File "/home/gerka/Desktop/kekMyPek/vol_bot/main.py", line 38, in main
    kLineDf = getKline(symbol, interval, Limit)
              ^^^^^^^^^^^^^^^^^^^^^^^^^^^^^^^^^
  File "/home/gerka/Desktop/kekMyPek/vol_bot/getData.py", line 21, in getKline
    rawReq = session.get_kline(
             ^^^^^^^^^^^^^^^^^^
  File "/home/gerka/Desktop/kekMyPek/vol_bot/venv/lib/python3.11/site-packages/pybit/_v5_market.py", line 33, in get_kline
    return self._submit_request(
           ^^^^^^^^^^^^^^^^^^^^^
  File "/home/gerka/Desktop/kekMyPek/vol_bot/venv/lib/python3.11/site-packages/pybit/_http_manager.py", line 297, in _submit_request
    raise e
  File "/home/gerka/Desktop/kekMyPek/vol_bot/venv/lib/python3.11/site-packages/pybit/_http_manager.py", line 284, in _submit_request
    s = self.client.send(r, timeout=self.timeout)
        ^^^^^^^^^^^^^^^^^^^^^^^^^^^^^^^^^^^^^^^^^
  File "/home/gerka/Desktop/kekMyPek/vol_bot/venv/lib/python3.11/site-packages/requests/sessions.py", line 703, in send
    r = adapter.send(request, **kwargs)
        ^^^^^^^^^^^^^^^^^^^^^^^^^^^^^^^
  File "/home/gerka/Desktop/kekMyPek/vol_bot/venv/lib/python3.11/site-packages/requests/adapters.py", line 700, in send
    raise ConnectionError(e, request=request)
requests.exceptions.ConnectionError: HTTPSConnectionPool(host='api.bybit.com', port=443): Max retries exceeded with url: /v5/market/kline?category=linear&end=False&interval=60&limit=500&start=False&symbol=1INCHUSDT (Caused by NameResolutionError("<urllib3.connection.HTTPSConnection object at 0x7f536f3f1c50>: Failed to resolve 'api.bybit.com' ([Errno -2] Name or service not known)"))
